<?xml version='1.0'?>
<robot name="simple_model" xmlns:xacro="http://ros.org/wiki/xacro">


  <link name="world"/>

  <joint name="fixed" type="fixed">
    <parent link="world"/>
    <child link="link_0"/>
  </joint>


  <link name='link_0'>
    <inertial>
      <origin xyz="0 0 0.5" rpy="0 0 0"/>
      <mass value="1"/>
      <inertia
        ixx="0.166667" ixy="0.0" ixz="0.0"
        iyy="0.166667" iyz="0.0"
        izz="0.166667"/>
    </inertial>

    <visual>
      <origin rpy="0 0 0" xyz = "0 0 0.5"/>
      <geometry>
        <box size="0.2 0.2 1"/>
      </geometry>
    </visual>

    <collision>
      <origin xyz="0 0 0.5" rpy="0 0 0"/>
      <geometry>
        <box size="0.2 0.2 1"/>
      </geometry>
    </collision>
  </link>  


  <link name='link_1'>
    <inertial>
      <origin xyz="0 0 0.1" rpy="0 0 0"/>
      <mass value="1"/>
      <inertia
        ixx="0.166667" ixy="0.0" ixz="0.0"
        iyy="0.166667" iyz="0.0"
        izz="0.166667"/>
    </inertial>

    <visual>
      <origin rpy="0 0 0" xyz = "0 0 0.1"/>
      <geometry>
        <box size="1 0.2 0.2"/>
      </geometry>
    </visual>

    <collision>
      <origin rpy="0 0 0" xyz = "0 0 0.1"/>      
      <geometry>
        <box size="1 0.2 0.2"/>
      </geometry>
    </collision>
  </link>  



  <joint name="link_0_JOINT_0" type="continuous">
      <axis xyz="0 0 1"/>
      <origin rpy="0 0 0" xyz="0 0 1"/>
      <parent link = "link_0"/>
      <child link="link_1"/>
      <dynamics damping="0"/>
  </joint>





</robot>


